Workbook

Sheet Comparison
A1: Combined Data | B1: POST /quotes | C1: Mapped | D1: PUT /quotes | E1: Mapped | F1: POST /transfers | G1: Mapped | H1: PUT /transfers | I1: Mapped | J1: Definition
A2: Description | B2: Request that a Peer FSP create a new quote for performing a transaction. | D2: Callback to inform a Peer FSP about a previously- requested quote. | F2: Request a Peer FSP to perform the transfer of funds related to a transaction. | H2: Callback to inform a Peer FSP about a previously-performed transfer. | J2: Primary | K2: Secondary
A3: quoteId | B3: quoteId | C3: Yes | D3: quoteId (from URI) | J3: Common ID between the FSPs for the quote object, decided by the Payer FSP. The ID should be reused for resends of the same quote for a transaction. A new ID should be generated for each new quote for a transaction.
A4: transactionId | B4: transactionId | C4: Yes | J4: Common ID (decided by the Payer FSP) between the FSPs for the future transaction object. The actual transaction will be created as part of a successful transfer process. The ID should be reused for resends of the same quote for a transaction. A new ID should be generated for each new quote for a transaction.
A5: transferId | C5: No | F5: transferId | G5: Yes | H5: transferId (from URI) | I5: Yes | J5: The common ID between the FSPs and the optional Switch for the transfer object, decided by the Payer FSP. The ID should be reused for resends of the same transfer. A new ID should be generated for each new transfer.
A6: transactionRequestId | B6: transactionRequestId | C6: No | J6: Identifies an optional previously-sent transaction request.
A7: payee | B7: payee | C7: N/A | J7: Information about the Payee in the proposed financial transaction.
A8: payee.partyIdInfo | B8: payee.partyIdInfo | C8: N/A | J8: Party Id type, id, sub ID or type, and FSP Id.
A9: payee.partyIdInfo.partyIdType | B9: payee.partyIdInfo.partyIdType | C9: Yes | J9: The type of the identifier.
A10: payee.partyIdInfo.partyIdentifier | B10: payee.partyIdInfo.partyIdentifier | C10: Yes | J10: An identifier for the Party.
A11: payee.partyIdInfo.partySubIdOrType | B11: payee.partyIdInfo.partySubIdOrType | C11: Yes | J11: A sub-identifier or sub-type for the Party.
A12: payee.partyIdInfo.fspId | B12: payee.partyIdInfo.fspId | C12: Yes | F12: payeeFsp | G12: Yes | J12: The FSP identifier. | K12: Payee FSP in the proposed financial transaction.
A13: payee.partyIdInfo.extensionList | B13: payee.partyIdInfo.extensionList | C13: N/A | J13: Optional list of extensions to the payee information, specific to deployment.
A14: payee.partyIdInfo.extensionList.extension | B14: payee.partyIdInfo.extensionList.extension | C14: N/A | J14: An optional extension element defined by a key-value pair
A15: payee.partyIdInfo.extensionList.extension.key | B15: payee.partyIdInfo.extensionList.extension.key | C15: No | J15: The key for an optional extension element value
A16: payee.partyIdInfo.extensionList.extension.value | B16: payee.partyIdInfo.extensionList.extension.value | C16: No | J16: The value for an optional extension element key
A17: payee.merchantClassificationCode | B17: payee.merchantClassificationCode | C17: Yes | J17: A limited set of pre-defined numbers. This list would be a limited set of numbers identifying a set of popular merchant types like School Fees, Pubs and Restaurants, Groceries, and so on.
A18: payee.name | B18: payee.name | C18: Yes | J18: The name of the party, could be a real name or a nick name.
A19: payee.personalInfo | B19: payee.personalInfo | C19: N/A | J19: Personal information used to verify identity of Party such as first, middle, last name and date of birth.
A20: payee.personalInfo.complexName | B20: payee.personalInfo.complexName | C20: N/A | J20: First, middle and last name.
A21: payee.personalInfo.complexName.firstName | B21: payee.personalInfo.complexName.firstName | C21: Yes | J21: First name
A22: payee.personalInfo.complexName.middleName | B22: payee.personalInfo.complexName.middleName | C22: Yes | J22: Middle name
A23: payee.personalInfo.complexName.lastName | B23: payee.personalInfo.complexName.lastName | C23: Yes | J23: Last name
A24: payee.personalInfo.dateOfBirth | B24: payee.personalInfo.dateOfBirth | C24: Yes | J24: Date of birth
... A29: payer.partyIdInfo.partySubIdOrType | B29: payer.partyIdInfo.partySubIdOrType | C29: Yes | J29: A sub-identifier or sub-type for the Party.
A30: payer.partyIdInfo.fspId | B30: payer.partyIdInfo.fspId | C30: Yes | F30: payerFsp | G30: Yes | J30: The FSP identifier. | K30: Payer FSP in the proposed financial transaction.
A31: payer.partyIdInfo.extensionList | B31: payer.partyIdInfo.extensionList | C31: N/A | J31: Optional list of extensions to the payer information, specific to deployment.
A32: payer.partyIdInfo.extensionList.extension | B32: payer.partyIdInfo.extensionList.extension | C32: N/A | J32: An optional extension element defined by a key-value pair
A33: payer.partyIdInfo.extensionList.extension.key | B33: payer.partyIdInfo.extensionList.extension.key | C33: No | J33: The key for an optional extension element value
A34: payer.partyIdInfo.extensionList.extension.value | B34: payer.partyIdInfo.extensionList.extension.value | C34: No | J34: The value for an optional extension element key
A35: payer.merchantClassificationCode | B35: payer.merchantClassificationCode | C35: Yes | J35: A limited set of pre-defined numbers. This list would be a limited set of numbers identifying a set of popular merchant types like School Fees, Pubs and Restaurants, Groceries, and so on.
A36: payer.name | B36: payer.name | C36: Yes | J36: The name of the party, could be a real name or a nick name.
A37: payer.personalInfo | B37: payer.personalInfo | C37: N/A | J37: Personal information used to verify identity of Party such as first, middle, last name and date of birth.
A38: payer.personalInfo.complexName | B38: payer.personalInfo.complexName | C38: N/A | J38: First, middle and last name.
A39: payer.personalInfo.complexName.firstName | B39: payer.personalInfo.complexName.firstName | C39: Yes | J39: First name
A40: payer.personalInfo.complexName.middleName | B40: payer.personalInfo.complexName.middleName | C40: Yes | J40: Middle name
A41: payer.personalInfo.complexName.lastName | B41: payer.personalInfo.complexName.lastName | C41: Yes | J41: Last name
A42: payer.personalInfo.dateOfBirth | B42: payer.personalInfo.dateOfBirth | C42: Yes | J42: Date of birth
A43: amountType | B43: amountType | C43: No | J43: This element contains the amount type. Allowed values are: SEND (The amount the Payer would like to send, that is, the amount that should be withdrawn from the Payer account including any fees.) or RECEIVE (The amount the Payer would like the Payee to receive, that is, the amount that should be sent to the receiver exclusive fees.)
A44: amount | B44: amount | C44: Yes | F44: amount | G44: N/A | J44: Depending on amountType: If SEND: The amount the Payer would like to send, that is, the amount that should be withdrawn from the Payer account including any fees. The amount is updated by each participating entity in the transaction. If RECEIVE: The amount the Payee should receive, that is, the amount that should be sent to the receiver exclusive any fees. The amount is not updated by any of the participating entities.
...

Sheet pain.001.001.11
A1: ISO20022 data element | B1: Xpath | C1: Value | D1: Type | E1: Description | F1: Notes
A2: CustomerCreditTransferInitiationV11.GroupHeader.MessageIdentification | B2: Document.CstmrCdtTrfInitn.GrpHdr.MsgId | C2: Generate fresh UUID | D2: Max35Text | E2: Point to point reference, as assigned by the instructing party, and sent to the next party in the chain to unambiguously identify the message.
A3: CustomerCreditTransferInitiationV11.GroupHeader.CreationDateTime | B3: Document.CstmrCdtTrfInitn.GrpHdr.CreDtTm | C3: Timestamp at the time the message is received by the TMS API | D3: ISODateTime | E3: Date and time at which the message was created.
A4: CustomerCreditTransferInitiationV11.GroupHeader.NumberOfTransactions | B4: Document.CstmrCdtTrfInitn.GrpHdr.NbOfTxs | C4: 1 | D4: Max15NumericText | E4: Number of individual transactions contained in the message.
A5: CustomerCreditTransferInitiationV11.GroupHeader.InitiatingParty.Name | B5: Document.CstmrCdtTrfInitn.GrpHdr.InitgPty.Nm | C5: ="IF " & Comparison!$B$65& " = 'PAYER' THEN " & A14 & " ELSE " & A32 -> IF transactionType.initiator = 'PAYER' THEN CustomerCreditTransferInitiationV11.PaymentInformation.Debtor.Name ELSE CustomerCreditTransferInitiationV11.PaymentInformation.CreditTransferTransactionInformation.Creditor.Name | D5: Max140Text | E5: Name by which a party is known and which is usually used to identify that party.
A6: CustomerCreditTransferInitiationV11.GroupHeader.InitiatingParty.Identification.PrivateIdentification.DateAndPlaceOfBirth.BirthDate | C6: ="IF " & Comparison!$B$65& " = 'PAYER' THEN " & A15 & " ELSE " & A33 -> IF transactionType.initiator = 'PAYER' THEN CustomerCreditTransferInitiationV11.PaymentInformation.Debtor.Identification.PrivateIdentification.DateAndPlaceOfBirth.BirthDate ELSE CustomerCreditTransferInitiationV11.PaymentInformation.CreditTransferTransactionInformation.Creditor.Identification.PrivateIdentification.DateAndPlaceOfBirth.BirthDate | D6: ISODate | E6: Unique and unambiguous identification of a party.
A7: CustomerCreditTransferInitiationV11.GroupHeader.InitiatingParty.Identification.PrivateIdentification.Other.Identification | C7: ="IF " & Comparison!$B$65& " = 'PAYER' THEN " & A16 & " ELSE " & A34 -> IF transactionType.initiator = 'PAYER' THEN CustomerCreditTransferInitiationV11.PaymentInformation.Debtor.Identification.PrivateIdentification.Other.Identification ELSE CustomerCreditTransferInitiationV11.PaymentInformation.CreditTransferTransactionInformation.Creditor.Identification.PrivateIdentification.Other.Identification | D7: Max35Text | E7: Unique and unambiguous identification of a person.
A8: CustomerCreditTransferInitiationV11.GroupHeader.InitiatingParty.Identification.PrivateIdentification.Other.SchemeName.Proprietary | C8: ="IF " & Comparison!$B$65& " = 'PAYER' THEN " & A17 & " ELSE " & A35 -> IF transactionType.initiator = 'PAYER' THEN CustomerCreditTransferInitiationV11.PaymentInformation.Debtor.Identification.PrivateIdentification.Other.SchemeName.Proprietary ELSE CustomerCreditTransferInitiationV11.PaymentInformation.CreditTransferTransactionInformation.Creditor.Identification.PrivateIdentification.Other.SchemeName.Proprietary | D8: Max35Text | E8: Name of the identification scheme, in a free text form.
A9: CustomerCreditTransferInitiationV11.GroupHeader.InitiatingParty.ContactDetails.MobileNumber | C9: ="IF " & Comparison!$B$65& " = 'PAYER' THEN " & A18 & " ELSE " & A36 -> IF transactionType.initiator = 'PAYER' THEN CustomerCreditTransferInitiationV11.PaymentInformation.Debtor.ContactDetails.MobileNumber ELSE CustomerCreditTransferInitiationV11.PaymentInformation.CreditTransferTransactionInformation.Creditor.ContactDetails.MobileNumber | D9: PhoneNumber | E9: Collection of information that identifies a mobile phone number, as defined by telecom services.
A10: CustomerCreditTransferInitiationV11.PaymentInformation.PaymentInformationIdentification | C10: =Comparison!B3 -> quoteId | D10: Max35Text | E10: Unique identification, as assigned by a sending party, to unambiguously identify the payment information group within the message.
A11: CustomerCreditTransferInitiationV11.PaymentInformation.PaymentMethod | C11: TRA | D11: PaymentMethod3Code | E11: Specifies the transfer method that will be used to transfer the cash. (TRA - TransferAdvice: Transfer of an amount of money in the books of the account servicer. An advice should be sent back to the account owner.)
A12: CustomerCreditTransferInitiationV11.PaymentInformation.RequestedAdviceType.DebitAdvice.Code | C12: ADWD | D12: PaymentMethod3Code | E12: Specifies the transfer method that will be used to transfer the cash. (TRA - TransferAdvice: Transfer of an amount of money in the books of the account servicer. An advice should be sent back to the account owner.)
A13: CustomerCreditTransferInitiationV11.PaymentInformation.RequestedExecutionDate.DateTime | C13: =A3 -> CustomerCreditTransferInitiationV11.GroupHeader.CreationDateTime | D13: ISODateTime | E13: Date at which the initiating party requests the clearing agent to process the payment. Usage: This is the date on which the debtor's account is to be debited. If payment by cheque, the date when the cheque must be generated by the bank. | F13: This is a mandatory field in the ISO message, though this does not make a lot of sense in an instant payments environment. For now, set this date the same as the message creation date/time
A14: CustomerCreditTransferInitiationV11.PaymentInformation.Debtor.Name | C14: =Comparison!B39 & " & " & Comparison!B40 & " & " & Comparison!B41 -> payer.personalInfo.complexName.firstName & payer.personalInfo.complexName.middleName & payer.personalInfo.complexName.lastName | D14: Max140Text | E14: Name by which a party is known and which is usually used to identify that party.
A15: CustomerCreditTransferInitiationV11.PaymentInformation.Debtor.Identification.PrivateIdentification.DateAndPlaceOfBirth.BirthDate | C15: =Comparison!B42 -> payer.personalInfo.dateOfBirth | D15: ISODate | E15: Unique and unambiguous identification of a party.
A16: CustomerCreditTransferInitiationV11.PaymentInformation.Debtor.Identification.PrivateIdentification.Other.Identification | C16: =Comparison!B28 -> payer.partyIdInfo.partyIdentifier | D16: Max35Text | E16: Unique and unambiguous identification of a person.
A17: CustomerCreditTransferInitiationV11.PaymentInformation.Debtor.Identification.PrivateIdentification.Other.SchemeName.Proprietary | C17: ="IF "&Comparison!B27& " = 'PERSONAL_ID' THEN "&Comparison!B29&" ELSE "&Comparison!B27 -> IF payer.partyIdInfo.partyIdType = 'PERSONAL_ID' THEN payer.partyIdInfo.partySubIdOrType ELSE payer.partyIdInfo.partyIdType | D17: Max35Text | E17: Name of the identification scheme, in a free text form.
A18: CustomerCreditTransferInitiationV11.PaymentInformation.Debtor.ContactDetails.MobileNumber | C18: ="IF "&Comparison!B27& " = 'MSISDN' THEN "&Comparison!B28&" ELSE NULL" -> IF payer.partyIdInfo.partyIdType = 'MSISDN' THEN payer.partyIdInfo.partyIdentifier ELSE NULL | D18: PhoneNumber | E18: Collection of information that identifies a mobile phone number, as defined by telecom services.
A19: CustomerCreditTransferInitiationV11.PaymentInformation.DebtorAccount.Identification.Other.Identification | C19: =Comparison!B28 -> payer.partyIdInfo.partyIdentifier | D19: Max34Text | E19: Identification assigned by an institution.
A20: CustomerCreditTransferInitiationV11.PaymentInformation.DebtorAccount.Identification.Other.Identification.SchemeName.Proprietary | C20: ="IF "&Comparison!B27& " = 'PERSONAL_ID' THEN "&Comparison!B29&" ELSE "&Comparison!B27 -> IF payer.partyIdInfo.partyIdType = 'PERSONAL_ID' THEN payer.partyIdInfo.partySubIdOrType ELSE payer.partyIdInfo.partyIdType | D20: Max35Text | E20: Name of the identification scheme, in a free text form.
A21: CustomerCreditTransferInitiationV11.PaymentInformation.DebtorAccount.Name | C21: =Comparison!B36 -> payer.name | D21: Max70Text | E21: Name of the account, as assigned by the account servicing institution, in agreement with the account owner in order to provide an additional means of identification of the account. Usage: The account name is different from the account owner name. The account name is used in certain user communities to provide a means of identifying the account, in addition to the account owner's identity and the account number.
A22: CustomerCreditTransferInitiationV11.PaymentInformation.DebtorAgent.FinancialInstitutionIdentification.ClearingSystemMemberIdentification.MemberIdentification | C22: =Comparison!B30 -> payer.partyIdInfo.fspId | D22: Max35Text | E22: Identification of a member of a clearing system.
A23: CustomerCreditTransferInitiationV11.PaymentInformation.CreditTransferTransactionInformation.PaymentIdentification.EndToEndIdentification | C23: =Comparison!B4 -> transactionId | D23: Max35Text | E23: Unique identification assigned by the initiating party to unambiguously identify the transaction. This identification is passed on, unchanged, throughout the entire end-to-end chain. Usage: The end-to-end identification can be used for reconciliation or to link tasks relating to the transaction. It can be included in several messages related to the transaction. | F23: This might be the CustomerCreditTransferInitiationV11.PaymentInformation.CreditTransferTransactionInformation.PaymentIdentification.UETR instead since it is a UUIDv4 Identifier. To be confirmed.
A24: CustomerCreditTransferInitiation.PaymentInformation.CreditTransferTransaction.PaymentTypeInformation.CategoryPurpose.Proprietary | C24: ="IF " & Comparison!B64 & " = NULL THEN " & Comparison!B63 & " ELSE " & Comparison!B63 & " & " & Comparison!B64 -> IF transactionType.subScenario = NULL THEN transactionType.scenario ELSE transactionType.scenario & transactionType.subScenario | D24: Max35Text | E24: Specifies the high level purpose of the instruction based on a set of pre-defined categories. Usage: This is used by the initiating party to provide information concerning the processing of the payment. It is likely to trigger special processing by any of the agents involved in the payment chain.
A25: CustomerCreditTransferInitiationV11.PaymentInformation.CreditTransferTransactionInformation.Amount.InstructedAmount.Amount | C25: ="IF " & Comparison!B43 & " = 'SEND' THEN " & Comparison!B46 & " ELSE " & Comparison!B46 & " + " & Comparison!B49 -> IF amountType = 'SEND' THEN amount.amount ELSE amount.amount + fees.amount | D25: ActiveOrHistoricCurrencyAndAmount | E25: Amount of money to be moved between the debtor and creditor, before deduction of charges, expressed in the currency as ordered by the initiating party. Usage: This amount has to be transported unchanged through the transaction chain.
A26: CustomerCreditTransferInitiationV11.PaymentInformation.CreditTransferTransactionInformation.Amount.InstructedAmount.Currency | C26: =Comparison!B45 -> amount.currency | D26: ActiveOrHistoricCurrencyAndAmount | E26: Amount of money to be moved between the debtor and creditor, before deduction of charges, expressed in the currency as ordered by the initiating party. Usage: This amount has to be transported unchanged through the transaction chain.
A27: CustomerCreditTransferInitiationV11.PaymentInformation.CreditTransferTransactionInformation.Amount.EquivalentAmount.Amount | C27: ="IF " & Comparison!B43 & " = 'SEND' THEN " & Comparison!B46 & " ELSE " & Comparison!B46 & " + " & Comparison!B49 -> IF amountType = 'SEND' THEN amount.amount ELSE amount.amount + fees.amount | D27: ActiveOrHistoricCurrencyAndAmount | E27: Amount of money to be moved between debtor and creditor, before deduction of charges, expressed in the currency of the debtor's account, and to be moved in a different currency. Usage: The first agent will convert the equivalent amount into the amount to be moved.
A28: CustomerCreditTransferInitiationV11.PaymentInformation.CreditTransferTransactionInformation.Amount.EquivalentAmount.Currency | C28: =Comparison!B45 -> amount.currency | D28: ActiveOrHistoricCurrencyAndAmount | E28: Amount of money to be moved between debtor and creditor, before deduction of charges, expressed in the currency of the debtor's account, and to be moved in a different currency. Usage: The first agent will convert the equivalent amount into the amount to be moved.
A29: CustomerCreditTransferInitiationV11.PaymentInformation.CreditTransferTransactionInformation.Amount.EquivalentAmount.CurrencyOfTransfer | C29: =Comparison!B45 -> amount.currency | D29: ActiveOrHistoricCurrencyCode | E29: Specifies the currency of the to be transferred amount, which is different from the currency of the debtor's account.
A30: CustomerCreditTransferInitiationV11.PaymentInformation.CreditTransferTransactionInformation.ChargeBearer | C30: DEBT | D30: ChargeBearerTypeCode | E30: Specifies which party(ies) will pay charges due for processing of the instruction.
A31: CustomerCreditTransferInitiationV11.PaymentInformation.CreditTransferTransactionInformation.CreditorAgent.FinancialInstitutionIdentification.ClearingSystemMemberIdentification.MemberIdentification | C31: =Comparison!B12 -> payee.partyIdInfo.fspId | D31: Max35Text | E31: Identification of a member of a clearing system.
A32: CustomerCreditTransferInitiationV11.PaymentInformation.CreditTransferTransactionInformation.Creditor.Name | C32: =Comparison!B21 & " & " & Comparison!B22 & " & " & Comparison!B23 -> payee.personalInfo.complexName.firstName & payee.personalInfo.complexName.middleName & payee.personalInfo.complexName.lastName | D32: Max140Text | E32: Name by which a party is known and which is usually used to identify that party.
A33: CustomerCreditTransferInitiationV11.PaymentInformation.CreditTransferTransactionInformation.Creditor.Identification.PrivateIdentification.DateAndPlaceOfBirth.BirthDate | C33: =Comparison!B24 -> payee.personalInfo.dateOfBirth | D33: ISODate | E33: Unique and unambiguous identification of a party.
A34: CustomerCreditTransferInitiationV11.PaymentInformation.CreditTransferTransactionInformation.Creditor.Identification.PrivateIdentification.Other.Identification | C34: =Comparison!B10 -> payee.partyIdInfo.partyIdentifier | D34: Max35Text | E34: Unique and unambiguous identification of a person.
A35: CustomerCreditTransferInitiationV11.PaymentInformation.CreditTransferTransactionInformation.Creditor.Identification.PrivateIdentification.Other.SchemeName.Proprietary | C35: ="IF "&Comparison!B9& " = 'PERSONAL_ID' THEN "&Comparison!B11&" ELSE "&Comparison!B9 -> IF payee.partyIdInfo.partyIdType = 'PERSONAL_ID' THEN payee.partyIdInfo.partySubIdOrType ELSE payee.partyIdInfo.partyIdType | D35: Max35Text | E35: Name of the identification scheme, in a free text form.
A36: CustomerCreditTransferInitiationV11.PaymentInformation.CreditTransferTransactionInformation.Creditor.ContactDetails.MobileNumber | C36: ="IF "&Comparison!B9& " = 'MSISDN' THEN "&Comparison!B10&" ELSE NULL" -> IF payee.partyIdInfo.partyIdType = 'MSISDN' THEN payee.partyIdInfo.partyIdentifier ELSE NULL | D36: PhoneNumber | E36: Collection of information that identifies a mobile phone number, as defined by telecom services.
A37: CustomerCreditTransferInitiationV11.PaymentInformation.CreditTransferTransactionInformation.CreditorAccount.Identification.Other.Identification | C37: =Comparison!B28 -> payer.partyIdInfo.partyIdentifier | D37: Max34Text | E37: Identification assigned by an institution.
A38: CustomerCreditTransferInitiationV11.PaymentInformation.CreditTransferTransactionInformation.CreditorAccount.Identification.Other.Identification.SchemeName.Proprietary | C38: ="IF "&Comparison!B9& " = 'PERSONAL_ID' THEN "&Comparison!B11&" ELSE "&Comparison!B9 -> IF payee.partyIdInfo.partyIdType = 'PERSONAL_ID' THEN payee.partyIdInfo.partySubIdOrType ELSE payee.partyIdInfo.partyIdType | D38: Max35Text | E38: Name of the identification scheme, in a free text form.
A39: CustomerCreditTransferInitiationV11.PaymentInformation.CreditTransferTransactionInformation.CreditorAccount.Name | C39: =Comparison!B18 -> payee.name | D39: Max70Text | E39: Name of the account, as assigned by the account servicing institution, in agreement with the account owner in order to provide an additional means of identification of the account. Usage: The account name is different from the account owner name. The account name is used in certain user communities to provide a means of identifying the account, in addition to the account owner's identity and the account number.
A40: CustomerCreditTransferInitiationV11.PaymentInformation.CreditTransferTransactionInformation.Purpose.Code | C40: MP2P | D40: ExternalPurpose1Code | E40: Underlying reason for the payment transaction, as published in an external purpose code list. | F40: This code denotes a Mobile Person-to-Person payment, which is the pre-dominant use of Mojaloop. Merchant payments will be introduced at some point and some logic will be required to identify whether this code is MP2P or MP2B.
...

Sheet pain.001.013.09
A1: ISO20022 data element | B1: Xpath | C1: Value | D1: Type | E1: Description | F1: Notes
A2: CreditorPaymentActivationRequestV09.GroupHeader.MessageIdentification | B2: Document.CstmrCdtTrfInitn.GrpHdr.MsgId | C2: Generate fresh UUID | D2: Max35Text | E2: Point to point reference, as assigned by the instructing party, and sent to the next party in the chain to unambiguously identify the message.
A3: CreditorPaymentActivationRequestV09.GroupHeader.CreationDateTime | B3: Document.CstmrCdtTrfInitn.GrpHdr.CreDtTm | C3: Timestamp at the time the message is received by the TMS API | D3: ISODateTime | E3: Date and time at which the message was created.
A4: CreditorPaymentActivationRequestV09.GroupHeader.NumberOfTransactions | B4: Document.CstmrCdtTrfInitn.GrpHdr.NbOfTxs | C4: 1 | D4: Max15NumericText | E4: Number of individual transactions contained in the message.
A5: CreditorPaymentActivationRequestV09.GroupHeader.InitiatingParty.Name | B5: Document.CstmrCdtTrfInitn.GrpHdr.InitgPty.Nm | C5: ='pain.001.001.11'!A5 & " {" & $C$10 & "}" -> CustomerCreditTransferInitiationV11.GroupHeader.InitiatingParty.Name {quoteId (from URI)} | D5: Max140Text | E5: Name by which a party is known and which is usually used to identify that party. | F5: Added through enrichment
A6: CreditorPaymentActivationRequestV09.GroupHeader.InitiatingParty.Identification.PrivateIdentification.DateAndPlaceOfBirth.BirthDate | C6: ='pain.001.001.11'!A6 & " {" & $C$10 & "}" -> CustomerCreditTransferInitiationV11.GroupHeader.InitiatingParty.Identification.PrivateIdentification.DateAndPlaceOfBirth.BirthDate {quoteId (from URI)} | D6: ISODate | E6: Unique and unambiguous identification of a party. | F6: Added through enrichment
A7: CreditorPaymentActivationRequestV09.GroupHeader.InitiatingParty.Identification.PrivateIdentification.Other.Identification | C7: ='pain.001.001.11'!A7 & " {" & $C$10 & "}" -> CustomerCreditTransferInitiationV11.GroupHeader.InitiatingParty.Identification.PrivateIdentification.Other.Identification {quoteId (from URI)} | D7: Max35Text | E7: Unique and unambiguous identification of a person. | F7: Added through enrichment
A8: CreditorPaymentActivationRequestV09.GroupHeader.InitiatingParty.Identification.PrivateIdentification.Other.SchemeName.Proprietary | C8: ='pain.001.001.11'!A8 & " {" & $C$10 & "}" -> CustomerCreditTransferInitiationV11.GroupHeader.InitiatingParty.Identification.PrivateIdentification.Other.SchemeName.Proprietary {quoteId (from URI)} | D8: Max35Text | E8: Name of the identification scheme, in a free text form. | F8: Added through enrichment
A9: CreditorPaymentActivationRequestV09.GroupHeader.InitiatingParty.ContactDetails.MobileNumber | C9: ='pain.001.001.11'!A9 & " {" & $C$10 & "}" -> CustomerCreditTransferInitiationV11.GroupHeader.InitiatingParty.ContactDetails.MobileNumber {quoteId (from URI)} | D9: PhoneNumber | E9: Collection of information that identifies a mobile phone number, as defined by telecom services. | F9: Added through enrichment
A10: CreditorPaymentActivationRequestV09.PaymentInformation.PaymentInformationIdentification | C10: =Comparison!D3 -> quoteId (from URI) | D10: Max35Text | E10: Unique identification, as assigned by a sending party, to unambiguously identify the payment information group within the message. | F10: Retrieved from incoming message URI
A11: CreditorPaymentActivationRequestV09.PaymentInformation.PaymentMethod | C11: ='pain.001.001.11'!A11 & " {" & $C$10 & "}" -> CustomerCreditTransferInitiationV11.PaymentInformation.PaymentMethod {quoteId (from URI)} | D11: PaymentMethod3Code | E11: Specifies the transfer method that will be used to transfer the cash. (TRA - TransferAdvice: Transfer of an amount of money in the books of the account servicer. An advice should be sent back to the account owner.) | F11: Added through enrichment
A12: CreditorPaymentActivationRequestV09.PaymentInformation.RequestedAdviceType.DebitAdvice.Code | C12: ='pain.001.001.11'!A12 & " {" & $C$10 & "}" -> CustomerCreditTransferInitiationV11.PaymentInformation.RequestedAdviceType.DebitAdvice.Code {quoteId (from URI)} | D12: PaymentMethod3Code | E12: Specifies the transfer method that will be used to transfer the cash. (TRA - TransferAdvice: Transfer of an amount of money in the books of the account servicer. An advice should be sent back to the account owner.) | F12: Added through enrichment
A13: CreditorPaymentActivationRequestV09.PaymentInformation.RequestedExecutionDate.DateTime | C13: =A3 -> CreditorPaymentActivationRequestV09.GroupHeader.CreationDateTime | D13: ISODateTime | E13: Date at which the initiating party requests the clearing agent to process the payment. Usage: This is the date on which the debtor's account is to be debited. If payment by cheque, the date when the cheque must be generated by the bank. | F13: This is a mandatory field in the ISO message, though this does not make a lot of sense in an instant payments environment. For now, set this date the same as the message creation date/time
A14: CreditorPaymentActivationRequestV09.PaymentInformation.ExpiryDate.DateTime | C14: =Comparison!D75 -> expiration | D14: ISODateTime | E14: Date by which the debtor must have accepted or rejected the request. Usage: Beyond this date, the request becomes void and cannot be processed anymore.
A15: CreditorPaymentActivationRequestV09.PaymentInformation.Debtor.Name | C15: ='pain.001.001.11'!A14 & " {" & $C$10 & "}" -> CustomerCreditTransferInitiationV11.PaymentInformation.Debtor.Name {quoteId (from URI)} | D15: Max140Text | E15: Name by which a party is known and which is usually used to identify that party. | F15: Added through enrichment
A16: CreditorPaymentActivationRequestV09.PaymentInformation.Debtor.Identification.PrivateIdentification.DateAndPlaceOfBirth.BirthDate | C16: ='pain.001.001.11'!A15 & " {" & $C$10 & "}" -> CustomerCreditTransferInitiationV11.PaymentInformation.Debtor.Identification.PrivateIdentification.DateAndPlaceOfBirth.BirthDate {quoteId (from URI)} | D16: ISODate | E16: Unique and unambiguous identification of a party. | F16: Added through enrichment
A17: CreditorPaymentActivationRequestV09.PaymentInformation.Debtor.Identification.PrivateIdentification.Other.Identification | C17: ='pain.001.001.11'!A16 & " {" & $C$10 & "}" -> CustomerCreditTransferInitiationV11.PaymentInformation.Debtor.Identification.PrivateIdentification.Other.Identification {quoteId (from URI)} | D17: Max35Text | E17: Unique and unambiguous identification of a person. | F17: Added through enrichment
A18: CreditorPaymentActivationRequestV09.PaymentInformation.Debtor.Identification.PrivateIdentification.Other.SchemeName.Proprietary | C18: ='pain.001.001.11'!A17 & " {" & $C$10 & "}" -> CustomerCreditTransferInitiationV11.PaymentInformation.Debtor.Identification.PrivateIdentification.Other.SchemeName.Proprietary {quoteId (from URI)} | D18: Max35Text | E18: Name of the identification scheme, in a free text form. | F18: Added through enrichment
A19: CreditorPaymentActivationRequestV09.PaymentInformation.Debtor.ContactDetails.MobileNumber | C19: ='pain.001.001.11'!A18 & " {" & $C$10 & "}" -> CustomerCreditTransferInitiationV11.PaymentInformation.Debtor.ContactDetails.MobileNumber {quoteId (from URI)} | D19: PhoneNumber | E19: Collection of information that identifies a mobile phone number, as defined by telecom services. | F19: Added through enrichment
A20: CreditorPaymentActivationRequestV09.PaymentInformation.DebtorAccount.Identification.Other.Identification | C20: ='pain.001.001.11'!A19 & " {" & $C$10 & "}" -> CustomerCreditTransferInitiationV11.PaymentInformation.DebtorAccount.Identification.Other.Identification {quoteId (from URI)} | D20: Max34Text | E20: Identification assigned by an institution. | F20: Added through enrichment
A21: CreditorPaymentActivationRequestV09.PaymentInformation.DebtorAccount.Identification.Other.Identification.SchemeName.Proprietary | C21: ='pain.001.001.11'!A20 & " {" & $C$10 & "}" -> CustomerCreditTransferInitiationV11.PaymentInformation.DebtorAccount.Identification.Other.Identification.SchemeName.Proprietary {quoteId (from URI)} | D21: Max35Text | E21: Name of the identification scheme, in a free text form. | F21: Added through enrichment
A22: CreditorPaymentActivationRequestV09.PaymentInformation.DebtorAccount.Name | C22: ='pain.001.001.11'!A21 & " {" & $C$10 & "}" -> CustomerCreditTransferInitiationV11.PaymentInformation.DebtorAccount.Name {quoteId (from URI)} | D22: Max70Text | E22: Name of the account, as assigned by the account servicing institution, in agreement with the account owner in order to provide an additional means of identification of the account. Usage: The account name is different from the account owner name. The account name is used in certain user communities to provide a means of identifying the account, in addition to the account owner's identity and the account number. | F22: Added through enrichment
A23: CreditorPaymentActivationRequestV09.PaymentInformation.DebtorAgent.FinancialInstitutionIdentification.ClearingSystemMemberIdentification.MemberIdentification | C23: ='pain.001.001.11'!A22 & " {" & $C$10 & "}" -> CustomerCreditTransferInitiationV11.PaymentInformation.DebtorAgent.FinancialInstitutionIdentification.ClearingSystemMemberIdentification.MemberIdentification {quoteId (from URI)} | D23: Max35Text | E23: Identification of a member of a clearing system. | F23: Added through enrichment
A24: CreditorPaymentActivationRequestV09.PaymentInformation.CreditTransferTransactionInformation.PaymentIdentification.EndToEndIdentification | C24: ='pain.001.001.11'!A23 & " {" & $C$10 & "}" -> CustomerCreditTransferInitiationV11.PaymentInformation.CreditTransferTransactionInformation.PaymentIdentification.EndToEndIdentification {quoteId (from URI)} | D24: Max35Text | E24: Unique identification assigned by the initiating party to unambiguously identify the transaction. This identification is passed on, unchanged, throughout the entire end-to-end chain. Usage: The end-to-end identification can be used for reconciliation or to link tasks relating to the transaction. It can be included in several messages related to the transaction. | F24: Added through enrichment
A25: CustomerCreditTransferInitiation.PaymentInformation.CreditTransferTransaction.PaymentTypeInformation.CategoryPurpose.Proprietary | C25: ='pain.001.001.11'!A24 & " {" & $C$10 & "}" -> CustomerCreditTransferInitiation.PaymentInformation.CreditTransferTransaction.PaymentTypeInformation.CategoryPurpose.Proprietary {quoteId (from URI)} | D25: Max35Text | E25: Specifies the high level purpose of the instruction based on a set of pre-defined categories. Usage: This is used by the initiating party to provide information concerning the processing of the payment. It is likely to trigger special processing by any of the agents involved in the payment chain. | F25: Added through enrichment
A26: CreditorPaymentActivationRequestV09.PaymentInformation.CreditTransferTransactionInformation.Amount.InstructedAmount.Amount | C26: =Comparison!D52 -> transferAmount.amount | D26: ActiveOrHistoricCurrencyAndAmount | E26: Amount of money to be moved between the debtor and creditor, before deduction of charges, expressed in the currency as ordered by the initiating party. Usage: This amount has to be transported unchanged through the transaction chain.
A27: CreditorPaymentActivationRequestV09.PaymentInformation.CreditTransferTransactionInformation.Amount.InstructedAmount.Currency | C27: =Comparison!D51 -> transferAmount.currency | D27: ActiveOrHistoricCurrencyAndAmount | E27: Amount of money to be moved between the debtor and creditor, before deduction of charges, expressed in the currency as ordered by the initiating party. Usage: This amount has to be transported unchanged through the transaction chain.
A28: CreditorPaymentActivationRequestV09.PaymentInformation.CreditTransferTransactionInformation.Amount.EquivalentAmount.Amount | C28: =Comparison!D52 -> transferAmount.amount | D28: ActiveOrHistoricCurrencyAndAmount | E28: Amount of money to be moved between debtor and creditor, before deduction of charges, expressed in the currency of the debtor's account, and to be moved in a different currency. Usage: The first agent will convert the equivalent amount into the amount to be moved.
A29: CreditorPaymentActivationRequestV09.PaymentInformation.CreditTransferTransactionInformation.Amount.EquivalentAmount.Currency | C29: =Comparison!D51 -> transferAmount.currency | D29: ActiveOrHistoricCurrencyAndAmount | E29: Amount of money to be moved between debtor and creditor, before deduction of charges, expressed in the currency of the debtor's account, and to be moved in a different currency. Usage: The first agent will convert the equivalent amount into the amount to be moved.
A30: CreditorPaymentActivationRequestV09.PaymentInformation.CreditTransferTransactionInformation.Amount.EquivalentAmount.CurrencyOfTransfer | C30: =Comparison!B45 -> amount.currency | D30: ActiveOrHistoricCurrencyCode | E30: Specifies the currency of the to be transferred amount, which is different from the currency of the debtor's account.
A31: CreditorPaymentActivationRequestV09.PaymentInformation.CreditTransferTransactionInformation.ChargeBearer | C31: DEBT | D31: ChargeBearerTypeCode | E31: Specifies which party(ies) will pay charges due for processing of the instruction.
A32: CreditorPaymentActivationRequestV09.PaymentInformation.CreditTransferTransactionInformation.CreditorAgent.FinancialInstitutionIdentification.ClearingSystemMemberIdentification.MemberIdentification | C32: ='pain.001.001.11'!A31 & " {" & $C$10 & "}" -> CustomerCreditTransferInitiationV11.PaymentInformation.CreditTransferTransactionInformation.CreditorAgent.FinancialInstitutionIdentification.ClearingSystemMemberIdentification.MemberIdentification {quoteId (from URI)} | D32: Max35Text | E32: Identification of a member of a clearing system. | F32: Added through enrichment
A33: CreditorPaymentActivationRequestV09.PaymentInformation.CreditTransferTransactionInformation.Creditor.Name | C33: ='pain.001.001.11'!A32 & " {" & $C$10 & "}" -> CustomerCreditTransferInitiationV11.PaymentInformation.CreditTransferTransactionInformation.Creditor.Name {quoteId (from URI)} | D33: Max140Text | E33: Name by which a party is known and which is usually used to identify that party. | F33: Added through enrichment
A34: CreditorPaymentActivationRequestV09.PaymentInformation.CreditTransferTransactionInformation.Creditor.Identification.PrivateIdentification.DateAndPlaceOfBirth.BirthDate | C34: ='pain.001.001.11'!A33 & " {" & $C$10 & "}" -> CustomerCreditTransferInitiationV11.PaymentInformation.CreditTransferTransactionInformation.Creditor.Identification.PrivateIdentification.DateAndPlaceOfBirth.BirthDate {quoteId (from URI)} | D34: ISODate | E34: Unique and unambiguous identification of a party. | F34: Added through enrichment
A35: CreditorPaymentActivationRequestV09.PaymentInformation.CreditTransferTransactionInformation.Creditor.Identification.PrivateIdentification.Other.Identification | C35: ='pain.001.001.11'!A34 & " {" & $C$10 & "}" -> CustomerCreditTransferInitiationV11.PaymentInformation.CreditTransferTransactionInformation.Creditor.Identification.PrivateIdentification.Other.Identification {quoteId (from URI)} | D35: Max35Text | E35: Unique and unambiguous identification of a person. | F35: Added through enrichment
A36: CreditorPaymentActivationRequestV09.PaymentInformation.CreditTransferTransactionInformation.Creditor.Identification.PrivateIdentification.Other.SchemeName.Proprietary | C36: ='pain.001.001.11'!A35 & " {" & $C$10 & "}" -> CustomerCreditTransferInitiationV11.PaymentInformation.CreditTransferTransactionInformation.Creditor.Identification.PrivateIdentification.Other.SchemeName.Proprietary {quoteId (from URI)} | D36: Max35Text | E36: Name of the identification scheme, in a free text form. | F36: Added through enrichment
A37: CreditorPaymentActivationRequestV09.PaymentInformation.CreditTransferTransactionInformation.Creditor.ContactDetails.MobileNumber | C37: ='pain.001.001.11'!A36 & " {" & $C$10 & "}" -> CustomerCreditTransferInitiationV11.PaymentInformation.CreditTransferTransactionInformation.Creditor.ContactDetails.MobileNumber {quoteId (from URI)} | D37: PhoneNumber | E37: Collection of information that identifies a mobile phone number, as defined by telecom services. | F37: Added through enrichment
A38: CreditorPaymentActivationRequestV09.PaymentInformation.CreditTransferTransactionInformation.CreditorAccount.Identification.Other.Identification | C38: ='pain.001.001.11'!A37 & " {" & $C$10 & "}" -> CustomerCreditTransferInitiationV11.PaymentInformation.CreditTransferTransactionInformation.CreditorAccount.Identification.Other.Identification {quoteId (from URI)} | D38: Max34Text | E38: Identification assigned by an institution. | F38: Added through enrichment
A39: CreditorPaymentActivationRequestV09.PaymentInformation.CreditTransferTransactionInformation.CreditorAccount.Identification.Other.Identification.SchemeName.Proprietary | C39: ='pain.001.001.11'!A38 & " {" & $C$10 & "}" -> CustomerCreditTransferInitiationV11.PaymentInformation.CreditTransferTransactionInformation.CreditorAccount.Identification.Other.Identification.SchemeName.Proprietary {quoteId (from URI)} | D39: Max35Text | E39: Name of the identification scheme, in a free text form. | F39: Added through enrichment
A40: CreditorPaymentActivationRequestV09.PaymentInformation.CreditTransferTransactionInformation.CreditorAccount.Name | C40: ='pain.001.001.11'!A39 & " {" & $C$10 & "}" -> CustomerCreditTransferInitiationV11.PaymentInformation.CreditTransferTransactionInformation.CreditorAccount.Name {quoteId (from URI)} | D40: Max70Text | E40: Name of the account, as assigned by the account servicing institution, in agreement with the account owner in order to provide an additional means of identification of the account. Usage: The account name is different from the account owner name. The account name is used in certain user communities to provide a means of identifying the account, in addition to the account owner's identity and the account number. | F40: Added through enrichment
...

Sheet pacs.008.001.10
A1: ISO20022 data element | B1: Xpath | C1: Value | D1: Type | E1: Description | F1: Notes
A2: FIToFICustomerCreditTransferV10.GroupHeader.MessageIdentification | B2: Document.CstmrCdtTrfInitn.GrpHdr.MsgId | C2: Generate fresh UUID | D2: Max35Text | E2: Point to point reference, as assigned by the instructing party, and sent to the next party in the chain to unambiguously identify the message.
A3: FIToFICustomerCreditTransferV10.GroupHeader.CreationDateTime | B3: Document.CstmrCdtTrfInitn.GrpHdr.CreDtTm | C3: Timestamp at the time the message is received by the TMS API | D3: ISODateTime | E3: Date and time at which the message was created.
A4: FIToFICustomerCreditTransferV10.GroupHeader.NumberOfTransactions | B4: Document.CstmrCdtTrfInitn.GrpHdr.NbOfTxs | C4: 1 | D4: Max15NumericText | E4: Number of individual transactions contained in the message.
A5: FIToFICustomerCreditTransferV10.GroupHeader.SettlementInformation.SettlementMethod | C5: CLRG | D5: SettlementMethod1Code | E5: Specifies the method used to settle the credit transfer instruction.
A6: FIToFICustomerCreditTransferV10.CreditTransferTransactionInformation.PaymentIdentification.InstructionIdentification | C6: ='pain.001.013.09'!A10 & " {" & Comparison!$F$5 & "}" -> CreditorPaymentActivationRequestV09.PaymentInformation.PaymentInformationIdentification {transferId} | D6: Max35Text | E6: Unique identification, as assigned by an instructing party for an instructed party, to unambiguously identify the instruction. Usage: The instruction identification is a point to point reference that can be used between the instructing party and the instructed party to refer to the individual instruction. It can be included in several messages related to the instruction. | F6: Enriched from Quote via TransferID
A7: FIToFICustomerCreditTransferV10.CreditTransferTransactionInformation.PaymentIdentification.EndToEndIdentification | C7: =Comparison!F5 -> transferId | D7: Max35Text | E7: Unique identification assigned by the initiating party to unambiguously identify the transaction. This identification is passed on, unchanged, throughout the entire end-to-end chain. Usage: The end-to-end identification can be used for reconciliation or to link tasks relating to the transaction. It can be included in several messages related to the transaction. | F7: This might be the CustomerCreditTransferInitiationV11.PaymentInformation.CreditTransferTransactionInformation.PaymentIdentification.UETR instead since it is a UUIDv4 Identifier. To be confirmed.
A8: FIToFICustomerCreditTransferV10.CreditTransferTransactionInformation.InterbankSettlementAmount.Amount | C8: =Comparison!F46 -> amount.amount | D8: ActiveCurrencyAndAmount | E8: Amount of money moved between the instructing agent and the instructed agent.
A9: FIToFICustomerCreditTransferV10.CreditTransferTransactionInformation.InterbankSettlementAmount.Currency | C9: =Comparison!F45 -> amount.currency | D9: ActiveCurrencyAndAmount | E9: Amount of money moved between the instructing agent and the instructed agent.
A10: FIToFICustomerCreditTransferV10.CreditTransferTransactionInformation.InstructedAmount.Amount | C10: ='pain.001.013.09'!A26 & " {" & Comparison!$F$5 & "}" -> CreditorPaymentActivationRequestV09.PaymentInformation.CreditTransferTransactionInformation.Amount.InstructedAmount.Amount {transferId} | D10: ActiveCurrencyAndAmount | E10: Amount of money moved between the instructing agent and the instructed agent. | F10: Enriched from Quote via TransferID
A11: FIToFICustomerCreditTransferV10.CreditTransferTransactionInformation.InstructedAmount.Currency | C11: ='pain.001.013.09'!A27 & " {" & Comparison!$F$5 & "}" -> CreditorPaymentActivationRequestV09.PaymentInformation.CreditTransferTransactionInformation.Amount.InstructedAmount.Currency {transferId} | D11: ActiveCurrencyAndAmount | E11: Amount of money moved between the instructing agent and the instructed agent. | F11: Enriched from Quote via TransferID
A12: FIToFICustomerCreditTransferV10.CreditTransferTransactionInformation.ChargeBearer | C12: DEBT | D12: ChargeBearerTypeCode | E12: Specifies which party(ies) will pay charges due for processing of the instruction.
A13: FIToFICustomerCreditTransferV10.CreditTransferTransactionInformation.Charges[1].Amount.Amount | C13: ='pain.001.001.11'!A47 & " {" & Comparison!$F$5 & "}" -> CustomerCreditTransferInitiationV11.PaymentInformation.CreditTransferTransactionInformation.SupplementaryData.Envelope.Document.PayerFspFees.Amount {transferId} | D13: ActiveCurrencyAndAmount | E13: Transaction charges to be paid by the charge bearer. | F13: Enriched from Quote via TransferID
A14: FIToFICustomerCreditTransferV10.CreditTransferTransactionInformation.Charges[1].Amount.Currency | C14: ='pain.001.001.11'!A48 & " {" & Comparison!$F$5 & "}" -> CustomerCreditTransferInitiationV11.PaymentInformation.CreditTransferTransactionInformation.SupplementaryData.Envelope.Document.PayerFspFees.Currency {transferId} | D14: ActiveCurrencyAndAmount | E14: Transaction charges to be paid by the charge bearer. | F14: Enriched from Quote via TransferID
A15: FIToFICustomerCreditTransferV10.CreditTransferTransactionInformation.Charges[1].Agent.FinancialInstitutionIdentification.ClearingSystemMemberIdentification.MemberIdentification | C15: =Comparison!F30 -> payerFsp | D15: Max35Text | E15: Agent that takes the transaction charges or to which the transaction charges are due. | F15: Fees to the Payer FSP by the Payer
A16: FIToFICustomerCreditTransferV10.CreditTransferTransactionInformation.Charges[2].Amount.Amount | C16: ='pain.001.013.09'!A47 -> CreditorPaymentActivationRequestV09.PaymentInformation.CreditTransferTransactionInformation.SupplementaryData.Envelope.Document.PayeeFspFee.Amount | D16: ActiveCurrencyAndAmount | E16: Transaction charges to be paid by the charge bearer. | F16: Enriched from Quote via TransferID
A17: FIToFICustomerCreditTransferV10.CreditTransferTransactionInformation.Charges[2].Amount.Currency | C17: ='pain.001.013.09'!A48 -> CreditorPaymentActivationRequestV09.PaymentInformation.CreditTransferTransactionInformation.SupplementaryData.Envelope.Document.PayeeFspFee.Currency | D17: ActiveCurrencyAndAmount | E17: Transaction charges to be paid by the charge bearer. | F17: Enriched from Quote via TransferID
A18: FIToFICustomerCreditTransferV10.CreditTransferTransactionInformation.Charges[2].Agent.FinancialInstitutionIdentification.ClearingSystemMemberIdentification.MemberIdentification | C18: =Comparison!F12 -> payeeFsp | D18: Max35Text | E18: Agent that takes the transaction charges or to which the transaction charges are due. | F18: Fees to the Payee FSP by the Payer
A19: FIToFICustomerCreditTransferV10.CreditTransferTransactionInformation.Charges[3].Amount.Amount | C19: ='pain.001.013.09'!A49 -> CreditorPaymentActivationRequestV09.PaymentInformation.CreditTransferTransactionInformation.SupplementaryData.Envelope.Document.PayeeFspCommission.Amount | D19: ActiveCurrencyAndAmount | E19: Transaction charges to be paid by the charge bearer. | F19: Enriched from Quote via TransferID
A20: FIToFICustomerCreditTransferV10.CreditTransferTransactionInformation.Charges[3].Amount.Currency | C20: ='pain.001.013.09'!A50 -> CreditorPaymentActivationRequestV09.PaymentInformation.CreditTransferTransactionInformation.SupplementaryData.Envelope.Document.PayeeFspCommission.Currency | D20: ActiveCurrencyAndAmount | E20: Transaction charges to be paid by the charge bearer. | F20: Enriched from Quote via TransferID
A21: FIToFICustomerCreditTransferV10.CreditTransferTransactionInformation.Charges[3].Agent.FinancialInstitutionIdentification.ClearingSystemMemberIdentification.MemberIdentification | C21: =Comparison!F12 -> payeeFsp | D21: Max35Text | E21: Agent that takes the transaction charges or to which the transaction charges are due. | F21: Payee FSP commission to the Payer FSP by the Payer - Unsure if this is paid by the Payer as part of the total amount or the Payee FSP as a separate amount - TBC
A22: FIToFICustomerCreditTransferV10.CreditTransferTransactionInformation.InitiatingParty.Name | C22: ='pain.001.013.09'!A5 & " {" & Comparison!$F$5 & "}" -> CreditorPaymentActivationRequestV09.GroupHeader.InitiatingParty.Name {transferId} | D22: Max140Text | E22: Name by which a party is known and which is usually used to identify that party. | F22: Enriched from Quote via TransferID
A23: FIToFICustomerCreditTransferV10.CreditTransferTransactionInformation.InitiatingParty.Identification.PrivateIdentification.DateAndPlaceOfBirth.BirthDate | C23: ='pain.001.013.09'!A6 & " {" & Comparison!$F$5 & "}" -> CreditorPaymentActivationRequestV09.GroupHeader.InitiatingParty.Identification.PrivateIdentification.DateAndPlaceOfBirth.BirthDate {transferId} | D23: ISODate | E23: Unique and unambiguous identification of a party. | F23: Enriched from Quote via TransferID
A24: FIToFICustomerCreditTransferV10.CreditTransferTransactionInformation.InitiatingParty.Identification.PrivateIdentification.Other.Identification | C24: ='pain.001.013.09'!A7 & " {" & Comparison!$F$5 & "}" -> CreditorPaymentActivationRequestV09.GroupHeader.InitiatingParty.Identification.PrivateIdentification.Other.Identification {transferId} | D24: Max35Text | E24: Unique and unambiguous identification of a person. | F24: Enriched from Quote via TransferID
A25: FIToFICustomerCreditTransferV10.CreditTransferTransactionInformation.InitiatingParty.Identification.PrivateIdentification.Other.SchemeName.Proprietary | C25: ='pain.001.013.09'!A8 & " {" & Comparison!$F$5 & "}" -> CreditorPaymentActivationRequestV09.GroupHeader.InitiatingParty.Identification.PrivateIdentification.Other.SchemeName.Proprietary {transferId} | D25: Max35Text | E25: Name of the identification scheme, in a free text form. | F25: Enriched from Quote via TransferID
A26: FIToFICustomerCreditTransferV10.CreditTransferTransactionInformation.InitiatingParty.ContactDetails.MobileNumber | C26: ='pain.001.013.09'!A9 & " {" & Comparison!$F$5 & "}" -> CreditorPaymentActivationRequestV09.GroupHeader.InitiatingParty.ContactDetails.MobileNumber {transferId} | D26: PhoneNumber | E26: Collection of information that identifies a mobile phone number, as defined by telecom services. | F26: Enriched from Quote via TransferID
A27: FIToFICustomerCreditTransferV10.CreditTransferTransactionInformation.Debtor.Name | C27: ='pain.001.013.09'!A15 & " {" & Comparison!$F$5 & "}" -> CreditorPaymentActivationRequestV09.PaymentInformation.Debtor.Name {transferId} | D27: Max140Text | E27: Name by which a party is known and which is usually used to identify that party. | F27: Enriched from Quote via TransferID
A28: FIToFICustomerCreditTransferV10.CreditTransferTransactionInformation.Debtor.Identification.PrivateIdentification.DateAndPlaceOfBirth.BirthDate | C28: ='pain.001.013.09'!A16 & " {" & Comparison!$F$5 & "}" -> CreditorPaymentActivationRequestV09.PaymentInformation.Debtor.Identification.PrivateIdentification.DateAndPlaceOfBirth.BirthDate {transferId} | D28: ISODate | E28: Unique and unambiguous identification of a party. | F28: Enriched from Quote via TransferID
A29: FIToFICustomerCreditTransferV10.CreditTransferTransactionInformation.Debtor.Identification.PrivateIdentification.Other.Identification | C29: ='pain.001.013.09'!A17 & " {" & Comparison!$F$5 & "}" -> CreditorPaymentActivationRequestV09.PaymentInformation.Debtor.Identification.PrivateIdentification.Other.Identification {transferId} | D29: Max35Text | E29: Unique and unambiguous identification of a person. | F29: Enriched from Quote via TransferID
A30: FIToFICustomerCreditTransferV10.CreditTransferTransactionInformation.Debtor.Identification.PrivateIdentification.Other.SchemeName.Proprietary | C30: ='pain.001.013.09'!A18 & " {" & Comparison!$F$5 & "}" -> CreditorPaymentActivationRequestV09.PaymentInformation.Debtor.Identification.PrivateIdentification.Other.SchemeName.Proprietary {transferId} | D30: Max35Text | E30: Name of the identification scheme, in a free text form. | F30: Enriched from Quote via TransferID
A31: FIToFICustomerCreditTransferV10.CreditTransferTransactionInformation.Debtor.ContactDetails.MobileNumber | C31: ='pain.001.013.09'!A19 & " {" & Comparison!$F$5 & "}" -> CreditorPaymentActivationRequestV09.PaymentInformation.Debtor.ContactDetails.MobileNumber {transferId} | D31: PhoneNumber | E31: Collection of information that identifies a mobile phone number, as defined by telecom services. | F31: Enriched from Quote via TransferID
A32: FIToFICustomerCreditTransferV10.CreditTransferTransactionInformation.DebtorAccount.Identification.Other.Identification | C32: ='pain.001.013.09'!A20 & " {" & Comparison!$F$5 & "}" -> CreditorPaymentActivationRequestV09.PaymentInformation.DebtorAccount.Identification.Other.Identification {transferId} | D32: Max34Text | E32: Identification assigned by an institution. | F32: Enriched from Quote via TransferID
A33: FIToFICustomerCreditTransferV10.CreditTransferTransactionInformation.DebtorAccount.Identification.Other.Identification.SchemeName.Proprietary | C33: ='pain.001.013.09'!A21 & " {" & Comparison!$F$5 & "}" -> CreditorPaymentActivationRequestV09.PaymentInformation.DebtorAccount.Identification.Other.Identification.SchemeName.Proprietary {transferId} | D33: Max35Text | E33: Name of the identification scheme, in a free text form. | F33: Enriched from Quote via TransferID
A34: FIToFICustomerCreditTransferV10.CreditTransferTransactionInformation.DebtorAccount.Name | C34: ='pain.001.013.09'!A22 & " {" & Comparison!$F$5 & "}" -> CreditorPaymentActivationRequestV09.PaymentInformation.DebtorAccount.Name {transferId} | D34: Max70Text | E34: Name of the account, as assigned by the account servicing institution, in agreement with the account owner in order to provide an additional means of identification of the account. Usage: The account name is different from the account owner name. The account name is used in certain user communities to provide a means of identifying the account, in addition to the account owner's identity and the account number. | F34: Enriched from Quote via TransferID
A35: FIToFICustomerCreditTransferV10.CreditTransferTransactionInformation.DebtorAgent.FinancialInstitutionIdentification.ClearingSystemMemberIdentification.MemberIdentification | C35: =Comparison!F30 -> payerFsp | D35: Max35Text | E35: Identification of a member of a clearing system. | F35: Enriched from Quote via TransferID
A36: FIToFICustomerCreditTransferV10.CreditTransferTransactionInformation.CreditorAgent.FinancialInstitutionIdentification.ClearingSystemMemberIdentification.MemberIdentification | C36: =Comparison!F12 -> payeeFsp | D36: Max35Text | E36: Identification of a member of a clearing system. | F36: Enriched from Quote via TransferID
A37: FIToFICustomerCreditTransferV10.CreditTransferTransactionInformation.Creditor.Name | C37: ='pain.001.013.09'!A33 & " {" & Comparison!$F$5 & "}" -> CreditorPaymentActivationRequestV09.PaymentInformation.CreditTransferTransactionInformation.Creditor.Name {transferId} | D37: Max140Text | E37: Name by which a party is known and which is usually used to identify that party. | F37: Enriched from Quote via TransferID
A38: FIToFICustomerCreditTransferV10.CreditTransferTransactionInformation.Creditor.Identification.PrivateIdentification.DateAndPlaceOfBirth.BirthDate | C38: ='pain.001.013.09'!A34 & " {" & Comparison!$F$5 & "}" -> CreditorPaymentActivationRequestV09.PaymentInformation.CreditTransferTransactionInformation.Creditor.Identification.PrivateIdentification.DateAndPlaceOfBirth.BirthDate {transferId} | D38: ISODate | E38: Unique and unambiguous identification of a party. | F38: Enriched from Quote via TransferID
A39: FIToFICustomerCreditTransferV10.CreditTransferTransactionInformation.Creditor.Identification.PrivateIdentification.Other.Identification | C39: ='pain.001.013.09'!A35 & " {" & Comparison!$F$5 & "}" -> CreditorPaymentActivationRequestV09.PaymentInformation.CreditTransferTransactionInformation.Creditor.Identification.PrivateIdentification.Other.Identification {transferId} | D39: Max35Text | E39: Unique and unambiguous identification of a person. | F39: Enriched from Quote via TransferID
A40: FIToFICustomerCreditTransferV10.CreditTransferTransactionInformation.Creditor.Identification.PrivateIdentification.Other.SchemeName.Proprietary | C40: ='pain.001.013.09'!A36 & " {" & Comparison!$F$5 & "}" -> CreditorPaymentActivationRequestV09.PaymentInformation.CreditTransferTransactionInformation.Creditor.Identification.PrivateIdentification.Other.SchemeName.Proprietary {transferId} | D40: Max35Text | E40: Name of the identification scheme, in a free text form. | F40: Enriched from Quote via TransferID
...

Sheet pacs.002.001.12
A1: ISO20022 data element | B1: Xpath | C1: Value | D1: Type | E1: Description | F1: Notes
A2: FIToFIPaymentStatusReportV12.GroupHeader.MessageIdentification | B2: Document.CstmrCdtTrfInitn.GrpHdr.MsgId | C2: Generate fresh UUID | D2: Max35Text | E2: Point to point reference, as assigned by the instructing party, and sent to the next party in the chain to unambiguously identify the message.
A3: FIToFIPaymentStatusReportV12.GroupHeader.CreationDateTime | B3: Document.CstmrCdtTrfInitn.GrpHdr.CreDtTm | C3: Timestamp at the time the message is received by the TMS API | D3: ISODateTime | E3: Date and time at which the message was created.
